Workbook

Sheet BAU
A1: BAU Scenario | B1: Quantity | C1: Unit | D1: Source | E1: Comments
A2: Treated wastewater from Bengaluru
A3: Redirected for lake recharge | B3: =SUMIF(Sources!$H$3:$H$35,1,Sources!$F$3:$F$35) -> 564.69 | C3: MLD | D3: Ahmad and Singhal (2024), Annexure 3
A4: Total number of tanks supplied to | B4: 187 | C4: tanks | D4: Ahmad and Singhal (2024), pg 138 and pg 140 | E4: assuming tanks are lakes and that they have mentioned all the tanks in the report
A5: Per tank supply | B5: =B3/B4 -> 3.0197326 | C5: MLD per tank | D5: Calculated
A7: Devanahalli Demographics
A8: Total Population of Devanahalli town | B8: 38000 | C8: people | D8: Ahmad and Singhal (2024), pg 143
A9: Percentage of people in agricultural work | B9: =Sources!F75 -> 0.21381087 | C9: percent | D9: Primary census 2011 karnataka | E9: percentage from Bangalore rural district
A10: Number of people involved in agricultural work | B10: =$B$8*$B$9 -> 8124.8131 | C10: people | D10: Calculated
A11: Number of people not involved in agricultural work | B11: =B8-B10 -> 29875.187 | C11: people | D11: Calculated
A13: Devanahalli water pathway
A14: Total water demanded by Devanahalli town | B14: 2090000 | C14: Litres per day | D14: Ahmad and Singhal (2024), pg 143 | E14: using Devanahalli case study
A15: Number of tanks receiving water (Devanahalli) | B15: 9 | C15: tanks | D15: Ahmad and Singhal (2024), Table 31, pg 137
A16: Water supplied by revitalized well to town | B16: =Sources!A112 -> 159000 | C16: Litres per day | D16: Ahmad and Singhal (2024), pg 147 | E16: well near Sihineeru kere
A17: Percentage of water used for irrigation in agriculture | B17: 0.84 | C17: percent | D17: Ahmad and Singhal (2024), pg 143 (irrigate 84%) | E17: assuming Karnataka-wide value holds good here
A18: Percentage of water used for domestic use | B18: 0.08 | C18: percent | D18: Assumed | E18: assuming 8%
A19: Percentage of water used for drinking | B19: 0.08 | C19: percent | D19: Assumed | E19: assuming 8%
A20: Water from well used for irrigation in agriculture | B20: =$B$16*B17 -> 133560 | C20: Litres per day | D20: Calculated
A21: Water from well used for domestic use | B21: =$B$16*B18 -> 12720 | C21: Litres per day | D21: Calculated
A22: Water from well used for drinking | B22: =$B$16*B19 -> 12720 | C22: Litres per day | D22: Calculated
A24: Exposure to water
A25: Exposure to well water if involved in agricultural work | B25: =(B20/B10) + (B21/B8) + (B22/B8) -> 17.108006 | C25: Litres per day per person | D25: Calculated | E25: exposed to both irrigation water plus domestic and drinking water
A26: Exposure to well water if not involved in agricultural work | B26: =(B21/B8) + (B22/B8) -> 0.66947368 | C26: Litres per day per person | D26: Calculated | E26: exposed only to domestic and drinking water
A28: Chance of ingestion during irrigation | B28: 1e-05 | C28: percent | D28: Derived | E28: Ramesh et al. 2020 reports 0.1mL incidental ingestion per irrigation event. Assuming 10L of water is handled in such an event.
A29: Chance of ingestion during domestic use | B29: =B28*10 -> 0.0001 | C29: percent | D29: Assumed | E29: Assuming 10 times more likely to ingest during washing, bathing, etc., than during irrigation event.
A30: Chance of ingestion during drinking | B30: 1 | C30: percent | D30: Assumed
A32: Ingested volume of well water if involved in agricultural work | B32: =B28*(B20/B10) + B29*(B21/B8) + B30*(B22/B8) -> 0.3349347 | C32: Litres per day per person | D32: Calculated
A33: Ingested volume of well water if not involved in agricultural work | B33: =B29*(B21/B8) + B30*(B22/B8) -> 0.33477032 | C33: Litres per day per person | D33: Calculated
A35: Water Quality
A36: Concentration of E.coli | B36: =MIN(Sources!$B$59:$C$59) -> 9.12e-05 | C36: organisms per Litre | D36: George et al. 2015, Table 4 | E36: used the lower of both values, to simulate a better performing WTP
A37: Concentration of Rotavirus | B37: =MIN(Sources!$D$59:$E$59) -> 1.14e-08 | C37: organisms per Litre | D37: George et al. 2015, Table 4 | E37: used the lower of both values, to simulate a better performing WTP
A38: Concentration of Campylobacter | B38: =MIN(Sources!$F$59:$G$59) -> 0.0007524 | C38: organisms per Litre | D38: George et al. 2015, Table 4 | E38: used the lower of both values, to simulate a better performing WTP
A40: Exposure to Organisms
A41: Exposure to E.coli if involved in agricultural work | B41: =$B$32*B36 -> 3.0546045e-05 | C41: organisms per day per person | D41: Calculated | E41: Ingested volume x Concentration
A42: Exposure to Rotavirus if involved in agricultural work | B42: =$B$32*B37 -> 3.8182556e-09 | C42: organisms per day per person | D42: Calculated
A43: Exposure to Campylobacter if involved in agricultural work | B43: =$B$32*B38 -> 0.00025200487 | C43: organisms per day per person | D43: Calculated
A44: Exposure to E.coli if not involved in agricultural work | B44: =$B$33*B36 -> 3.0531053e-05 | C44: organisms per day per person | D44: Calculated
A45: Exposure to Rotavirus if not involved in agricultural work | B45: =$B$33*B37 -> 3.8163816e-09 | C45: organisms per day per person | D45: Calculated
A46: Exposure to Campylobacter if not involved in agricultural work | B46: =$B$33*B38 -> 0.00025188119 | C46: organisms per day per person | D46: Calculated
A48: Diarrheal Disease Risk
...

Sheet S2
A1: S2 Scenario | B1: Quantity | C1: Unit | D1: Source | E1: Comments
A2: Treated wastewater from Bengaluru
A3: Redirected for direct irrigation of farms | B3: =SUMIF(Sources!$H$3:$H$35,1,Sources!$F$3:$F$35) -> 564.69 | C3: MLD | D3: Ahmad and Singhal (2024), Annexure 3
A4: Total number of tanks supplied to | B4: 187 | C4: tanks | D4: Ahmad and Singhal (2024), pg 138 and pg 140 | E4: assuming tanks are lakes and that they have mentioned all the tanks in the report
A5: Per tank supply | B5: =B3/B4 -> 3.0197326 | C5: MLD per tank | D5: Calculated
A7: Devanahalli Demographics
A8: Total Population of Devanahalli town | B8: 38000 | C8: people | D8: Ahmad and Singhal (2024), pg 143
A9: Percentage of people in agricultural work | B9: =Sources!F75 -> 0.21381087 | C9: percent | D9: Primary census 2011 karnataka | E9: percentage from Bangalore rural district
A10: Number of people involved in agricultural work | B10: =$B$8*$B$9 -> 8124.8131 | C10: people | D10: Calculated
A11: Number of people not involved in agricultural work | B11: =B8-B10 -> 29875.187 | C11: people | D11: Calculated
A13: Devanahalli water pathway
A14: Total water demanded by Devanahalli town | B14: 2090000 | C14: Litres per day | D14: Ahmad and Singhal (2024), pg 143 | E14: using Devanahalli case study
A15: Number of tanks receiving water (Devanahalli) | B15: 9 | C15: tanks | D15: Ahmad and Singhal (2024), Table 31, pg 137
A16: Water supplied from TTP plant to town | B16: =Sources!A112 -> 159000 | C16: Litres per day | D16: Ahmad and Singhal (2024), pg 147 | E16: assuming TTP sends same amount of water as the well in the BAU
A17: Percentage of water used for irrigation in agriculture | B17: 1 | C17: percent | D17: Assumed | E17: assuming 100% because water not used for anything else
A18: Percentage of water used for domestic use | B18: 0 | C18: percent | D18: Assumed
A19: Percentage of water used for drinking | B19: 0 | C19: percent | D19: Assumed
A20: Water from well used for irrigation in agriculture | B20: =$B$16*B17 -> 159000 | C20: Litres per day | D20: Calculated
A21: Water from well used for domestic use | B21: =$B$16*B18 -> 0 | C21: Litres per day | D21: Calculated
A22: Water from well used for drinking | B22: =$B$16*B19 -> 0 | C22: Litres per day | D22: Calculated
A24: Exposure to water
A25: Exposure to well water if involved in agricultural work | B25: =(B20/B10) + (B21/B8) + (B22/B8) -> 19.569681 | C25: Litres per day per person | D25: Calculated | E25: exposed to both irrigation water plus domestic and drinking water
A26: Exposure to well water if not involved in agricultural work | B26: =(B21/B8) + (B22/B8) -> 0 | C26: Litres per day per person | D26: Calculated | E26: exposed only to domestic and drinking water
A28: Chance of ingestion during irrigation | B28: 1e-05 | C28: percent | D28: Derived | E28: Ramesh et al. 2020 reports 0.1mL incidental ingestion per irrigation event. Assuming 10L of water is handled in such an event.
A29: Chance of ingestion during domestic use | B29: =B28*10 -> 0.0001 | C29: percent | D29: Assumed | E29: Assuming 10 times more likely to ingest during washing, bathing, etc., than during irrigation event.
A30: Chance of ingestion during drinking | B30: 1 | C30: percent | D30: Assumed
A32: Ingested volume of well water if involved in agricultural work | B32: =B28*(B20/B10) + B29*(B21/B8) + B30*(B22/B8) -> 0.00019569681 | C32: Litres per day per person | D32: Calculated
A33: Ingested volume of well water if not involved in agricultural work | B33: =B29*(B21/B8) + B30*(B22/B8) -> 0 | C33: Litres per day per person | D33: Calculated
A35: Water Quality
A36: Concentration of E.coli | B36: =MIN(Sources!$B$58:$C$58) -> 9.12 | C36: organisms per Litre | D36: George et al. 2015, Table 4 | E36: used the better quality of raw water (Cauvery water) to simulate TTP
A37: Concentration of Rotavirus | B37: =MIN(Sources!$D$58:$E$58) -> 0.00114 | C37: organisms per Litre | D37: George et al. 2015, Table 4 | E37: used the better quality of raw water (Cauvery water) to simulate TTP
A38: Concentration of Campylobacter | B38: =MIN(Sources!$F$58:$G$58) -> 75.24 | C38: organisms per Litre | D38: George et al. 2015, Table 4 | E38: used the better quality of raw water (Cauvery water) to simulate TTP
A40: Exposure to Organisms
A41: Exposure to E.coli if involved in agricultural work | B41: =$B$32*B36 -> 0.0017847549 | C41: organisms per day per person | D41: Calculated | E41: Ingested volume x Concentration
A42: Exposure to Rotavirus if involved in agricultural work | B42: =$B$32*B37 -> 2.2309436e-07 | C42: organisms per day per person | D42: Calculated
A43: Exposure to Campylobacter if involved in agricultural work | B43: =$B$32*B38 -> 0.014724228 | C43: organisms per day per person | D43: Calculated
A44: Exposure to E.coli if not involved in agricultural work | B44: =$B$33*B36 -> 0 | C44: organisms per day per person | D44: Calculated
A45: Exposure to Rotavirus if not involved in agricultural work | B45: =$B$33*B37 -> 0 | C45: organisms per day per person | D45: Calculated
A46: Exposure to Campylobacter if not involved in agricultural work | B46: =$B$33*B38 -> 0 | C46: organisms per day per person | D46: Calculated
A48: Diarrheal Disease Risk
...

Sheet Sensitivity
A1: List of possible variants | B1: Comments | C1: Influence
A2: Total number of tanks the scheme supplies
A3: Total population of Devanahalli town
A4: % of Devanahalli population in agricultural work
A5: Number of tanks receiving water in Devanahalli
A6: Total water supplied from well/plant to town | B6: can vary quite a bit depending on town | C6: common to both
A7: % of water used for irrigation
A8: % of water used for domestic use
A9: % of water used for drinking
A10: Chance of ingestion during irrigation | B10: highly uncertain because of how I derived it | C10: common to both
A11: Chance of ingestion during domestic use | B11: highly uncertain because of how I derived it
A12: Chance of ingestion during drinking | B12: highly uncertain because of how I derived it
A13: E. coli concentration | B13: uncertain because secondary data from a different treatment plant / water body
A14: Rotavirus concentration | B14: uncertain because secondary data from a different treatment plant / water body
A15: Campylobacter concentration | B15: uncertain because secondary data from a different treatment plant / water body | C15: very high influence
A16: Dose-response parameter (r), per pathogen
A17: Probability of illness given infection, per pathogen
A18: % of wider population in agricultural work
A19: Disease burden per case (DALYs), per pathogen
A20: Karnataka GSDP per capita
A23: Total water supplied (common for both) | B23: BAU DALY | C23: S2 DALY | D23: Net DALY value | F23: Slope
A24: 159000 | B24: 126.85518 | C24: 1593.3923 | D24: 1466.5372 | F24: 0.0083
A25: 0 | B25: 0 | C25: 0 | D25: 0
A26: 2 | B26: 0.0015969354 | C26: 0.020984563 | D26: 0.019387628
A27: 1000 | B27: 0.79845993 | C27: 10.48923 | D27: 9.6907697
A28: 5000 | B28: 3.9922201 | C28: 52.385068 | D28: 48.392848
A29: 10000 | B29: 7.9842413 | C29: 104.61771 | D29: 96.633473
A30: 50000 | B30: 39.913246 | C30: 517.04662 | D30: 477.13337
A31: 100000 | B31: 79.806597 | C31: 1019.2592 | D31: 939.45261
A32: 500000 | B32: 398.23844 | C32: 4553.3121 | D32: 4155.0736
A34: Chance of ingestion of water during irrigation (common for both) | B34: BAU DALY | C34: S2 DALY | D34: Net DALY value | F34: Slope
A35: 1e-05 | B35: 126.85518 | C35: 1593.3923 | D35: 1466.5372 | F35: 100000000
A36: 5e-05 | B36: 126.96183 | C36: 6684.7677 | D36: 6557.8059
A37: 0.0001 | B37: 127.09515 | C37: 10934.373 | D37: 10807.278
A38: 5e-06 | B38: 126.84185 | C38: 815.11758 | D38: 688.27574
A39: 1e-06 | B39: 126.83118 | C39: 166.05682 | D39: 39.225638
A40: 7.6294e-07 | B40: 126.83055 | C40: 126.83041 | D40: -0.00013793153
A42: Campylobacter concentration (in BAU) | B42: BAU DALY | C42: S2 DALY | D42: Net DALY value | F42: Slope
A43: 0.0007524 | B43: 126.85518 | C43: 1593.3923 | D43: 1466.5372 | F43: -160084
A44: 0.003762 | B44: 612.13505 | C44: 1593.3923 | D44: 981.25728
...

Sheet Sources
A1: Annexure 3 of Ahmad and Singhal, 2024
A2: S. No. | B2: STP | C2: Location | D2: Total capacity utilized (MLD) | E2: Capacity utilized (MLD) | F2: Tread sewage reused (MLD) | G2: Used for | H2: Use_case_coded
A3: 1 | B3: Rajacanal | C3: Bengaluru | D3: 40 | E3: 32.68 | F3: 30.25 | G3: Irrigation and industrial | H3: 2 | J3: 1 | K3: Lake
A4: 2 | B4: Rajacanal | C4: Bengaluru | D4: 40 | E4: 40.51 | F4: 40.18 | G4: Irrigation and industrial | H4: 2 | J4: 2 | K4: Irrigation and industrial
A5: 3 | B5: Horamavu | C5: Bengaluru | D5: 20 | E5: 16.57 | F5: 14.96 | G5: Irrigation and industrial | H5: 2 | J5: 3 | K5: Others
A6: 4 | B6: Hebbal | C6: Bengaluru | D6: 100 | E6: 86.54 | F6: 84.5 | G6: Irrigation and industrial | H6: 2
A7: 5 | B7: K&C Valley | C7: Bengaluru | D7: 218 | E7: 153.66 | F7: 146.55 | G7: Lakes of Kolar | H7: 1
A8: 6 | B8: K&C Valley | C8: Bengaluru | D8: 30 | E8: 31.41 | F8: 30.27 | G8: Lakes of Kolar | H8: 1
A9: 7 | B9: Bellandur Amanikere | C9: Bengaluru | D9: 90 | E9: 88.2 | F9: 77.76 | G9: Lakes of Kolar | H9: 1
A10: 8 | B10: Jakkur | C10: Bengaluru | D10: 15 | E10: 17.18 | F10: 17.08 | G10: To KPTCL for power generation, remaining to Jakkuru lake | H10: 2
A11: 9 | B11: Sarakki | C11: Bengaluru | D11: 5 | E11: 4.77 | F11: 4.67 | G11: Proposal to recharge Sarakki lake | H11: 1
A12: 10 | B12: Lalbagh | C12: Bengaluru | D12: 1.5 | E12: 1.23 | F12: 1.17 | G12: Horticulture department | H12: 3
A13: 11 | B13: Cubbon Park | C13: Bengaluru | D13: 4 | E13: 2.5 | F13: 2.07 | G13: Horticulture | H13: 3
A14: 12 | B14: Yelhanka | C14: Bengaluru | D14: 10 | E14: 9.97 | F14: 1.76 | G14: Industrial | H14: 3
A15: 13 | B15: Yelemelle chetty | C15: Bengaluru | D15: 15 | E15: 13.63 | F15: 13.29 | G15: Lake | H15: 1
A16: 14 | B16: Chikkabanavar | C16: Bengaluru | D16: 5 | E16: 4.88 | F16: 4.59 | G16: Lake | H16: 1
A17: 15 | B17: Mailsandra | C17: Bengaluru | D17: 100 | E17: 80.03 | F17: 0.318 | G17: Horticulture | H17: 3
... A34: 32 | B34: Madiwala | C34: Bengaluru | D34: 4 | E34: 2.08 | F34: 1.99 | G34: Madiwala lake | H34: 1
A35: 33 | B35: V Valley | C35: Bengaluru | D35: 150 | E35: 142.46 | G35: SWD | H35: 3
A36: 34 | B36: Hassan | C36: Not Bengaluru | D36: 10 | E36: 10 | F36: 2 | G36: Agriculture
A37: 35 | B37: Belur | C37: Not Bengaluru | D37: 5 | E37: 2.4 | F37: 0.4 | G37: Agriculture
A38: 36 | B38: Belur | C38: Not Bengaluru | D38: 0.3 | E38: 0.3 | F38: 0.3 | G38: Agriculture
A39: 37 | B39: Bannuru | C39: Not Bengaluru | D39: 3.8 | E39: 1.7 | F39: 1.5 | G39: Agriculture
A40: 38 | B40: Bannuru | C40: Not Bengaluru | D40: 0.15 | E40: 0.06 | F40: 0.05 | G40: Agriculture
A41: 39 | B41: Arasikere | C41: Not Bengaluru | D41: 12 | E41: 6 | F41: 6 | G41: Agriculture
A42: 40 | B42: Channarayapatna | C42: Not Bengaluru | D42: 4.6 | E42: 4.6 | F42: 1 | G42: Agriculture
A43: 41 | B43: Holenarasipura | C43: Not Bengaluru | D43: 3 | E43: 3 | F43: 0.5 | G43: Agriculture
A44: 42 | B44: Birur | C44: Not Bengaluru | D44: 2.64 | E44: 0.3 | F44: 0.15 | G44: Agriculture
A45: 43 | B45: Muddebihal | C45: Not Bengaluru | D45: 5.24 | E45: 4 | F45: 4 | G45: Treated sewage is discharged into nala for agriculture purpose
A46: 44 | B46: Tumkur | C46: Not Bengaluru | D46: 6 | E46: 2.7 | F46: 2.3 | G46: Agriculture
A47: 45 | B47: Mangaluru | C47: Not Bengaluru | D47: 43.5 | E47: 27 | F47: 27 | G47: Industry
... A52: 50 | B52: Basavana Bagewadi | C52: Not Bengaluru | D52: 0.25 | E52: 0.2 | F52: 0.2 | G52: Agriculture
B53: Total | D53: =SUM(D3:D52) -> 1537.23 | E53: =SUM(E3:E52) -> 1296.17 | F53: =SUM(F3:F52) -> 883.652
A56: Table 4 George et al 2015
A57: Parameters | B57: Pathogenic E. coli - Melapura | C57: Pathogenic E. coli - Hongally | D57: Rotavirus - Melapura | E57: Rotavirus - Hongally | F57: Campylobacter - Melapura | G57: Campylobacter - Hongally
A58: Raw water quality (CR) | B58: 9.12 | C58: 18.24 | D58: 0.00114 | E58: 0.00228 | F58: 75.24 | G58: 150.48
A59: Drinking water quality (CD) | B59: 9.12e-05 | C59: 0.000182 | D59: 1.14e-08 | E59: 2.28e-08 | F59: 0.0007524 | G59: 0.0015048
A60: Exposure by drinking water (E) | B60: 9.35e-05 | C60: 0.000187 | D60: 1.17e-08 | E60: 2.34e-08 | F60: 0.000771 | G60: 0.001542
A61: Dose-response (r) | B61: 0.001 | C61: 0.001 | D61: 0.27 | E61: 0.27 | F61: 0.018 | G61: 0.018
A62: Risk of infection (Pinf,d) | B62: 9.35e-08 | C62: 1.87e-07 | D62: 3.15e-09 | E62: 6.31e-09 | F62: 1.39e-05 | G62: 2.78e-05
...
